## 章异常

### 认识异常

异常就是报错

```python
未定义错误
print(a)

E:\基础\venv\Scripts\python.exe E:/基础/补笔记/test.py
Traceback (most recent call last):
  File "E:/基础/补笔记/test.py", line 1, in <module>
    print(a)
NameError: name 'a' is not defined

Process finished with exit code 1

语法错误
for i in range(10)：

E:\基础\venv\Scripts\python.exe E:/基础/补笔记/test.py
  File "E:/基础/补笔记/test.py", line 1
    for i in range(10)：
                      ^
SyntaxError: invalid character in identifier

Process finished with exit code 1
```

```python
异常的本身是类的实例
print(help(TypeError))

E:\基础\venv\Scripts\python.exe E:/基础/补笔记/test.py
Help on class TypeError in module builtins:

class TypeError(Exception)
 |  Inappropriate argument type.
 |  
 |  Method resolution order:
 |      TypeError
 |      Exception
 |      BaseException
 |      object
 |  
 |  Methods defined here:
 |  
 |  __init__(self, /, *args, **kwargs)
 |      Initialize self.  See help(type(self)) for accurate signature.
 |  
 |  __new__(*args, **kwargs) from builtins.type
 |      Create and return a new object.  See help(type) for accurate signature.
 |  
 |  ----------------------------------------------------------------------
 |  Methods inherited from BaseException:
 |  
 |  __delattr__(self, name, /)
 |      Implement delattr(self, name).
 |  
 |  __getattribute__(self, name, /)
 |      Return getattr(self, name).
 |  
 |  __reduce__(...)
 |      helper for pickle
 |  
 |  __repr__(self, /)
 |      Return repr(self).
 |  
 |  __setattr__(self, name, value, /)
 |      Implement setattr(self, name, value).
 |  
 |  __setstate__(...)
 |  
 |  __str__(self, /)
 |      Return str(self).
 |  
 |  with_traceback(...)
 |      Exception.with_traceback(tb) --
 |      set self.__traceback__ to tb and return self.
 |  
 |  ----------------------------------------------------------------------
 |  Data descriptors inherited from BaseException:
 |  
 |  __cause__
 |      exception cause
 |  
 |  __context__
 |      exception context
 |  
 |  __dict__
 |  
 |  __suppress_context__
 |  
 |  __traceback__
 |  
 |  args

None

Process finished with exit code 0

```

```python
错误回溯
def a():
    aaa


def b():
    a()


def c():
    b()


c()

E:\基础\venv\Scripts\python.exe E:/基础/补笔记/test.py
Traceback (most recent call last):
  File "E:/基础/补笔记/test.py", line 10, in <module>
    c()
  File "E:/基础/补笔记/test.py", line 8, in c
    b()
  File "E:/基础/补笔记/test.py", line 5, in b
    a()
  File "E:/基础/补笔记/test.py", line 2, in a
    aaa
NameError: name 'aaa' is not defined

Process finished with exit code 1
```

### 处理异常

try.... except....  **必须成对出现**

try只有一个，except可以有多个

except 后面必须加 Exception

```python
如果 try 下面的代码有异常，就执行except里的代码，如果try
里的代码没错就执行try里的。
try:
    a

except:
    print('小伙子报错了')
    
E:\基础\venv\Scripts\python.exe E:/基础/补笔记/test.py
小伙子报错了

Process finished with exit code 0    
```

```python
捕获具体的异常
try:
    a

except NameError:
    print('定义错误')
    
E:\基础\venv\Scripts\python.exe E:/基础/补笔记/test.py
定义错误

Process finished with exit code 0

假如except后面的具体异常不是try里面代码报错的原因，那么整个代码就会报错
try:
    1/0

except NameError:
    print('定义错误')
    
E:\基础\venv\Scripts\python.exe E:/基础/补笔记/test.py
Traceback (most recent call last):
  File "E:/基础/补笔记/test.py", line 2, in <module>
    1/0
ZeroDivisionError: division by zero

Process finished with exit code 1
```

```python
# Exception  注意，语法错误捕获不到，其他都可以捕获
try:
    1/0

except Exception as e:
    print(e)
    
E:\基础\venv\Scripts\python.exe E:/基础/补笔记/test.py
division by zero

Process finished with exit code 0
```

#### 自动抛出异常

```python
try里面的语句没有错误，但是还是捕获到了错误，因为 raise 就是主动抛出异常
try:
    raise TypeError('这是一个类型错误')

except Exception as e:
    print(e)
    
E:\基础\venv\Scripts\python.exe E:/基础/补笔记/test.py
这是一个类型错误

Process finished with exit code 0
```

```python
# raise的案例
def func(name):
    if name == '刘鑫':
        raise TypeError('刘鑫有毒')


func('刘鑫')

E:\基础\venv\Scripts\python.exe E:/基础/补笔记/test.py
Traceback (most recent call last):
  File "E:/基础/补笔记/test.py", line 6, in <module>
    func('刘鑫')
  File "E:/基础/补笔记/test.py", line 3, in func
    raise TypeError('刘鑫有毒')
TypeError: 刘鑫有毒

Process finished with exit code 1
```

```python
# else在代码没错时执行，finally不管有错没错都执行
try:
    print(123)

except Exception as e:
    print(e)

else:
    print('代码没错时候执行')

finally:
    print('一定会执行')
    
E:\基础\venv\Scripts\python.exe E:/基础/补笔记/test.py
123
代码没错时候执行
一定会执行

Process finished with exit code 0
```

### 断言